Workbook
Name prioridad: #REF!
Name sistema: #REF!
Name status: #REF!
Name tipo: #REF!

Sheet Hoja1 (2)
B3: Prioridad | C3: 45782 | D3: 45828 | F3: Módulo | G3: 45782 | H3: 45828 | J3: Prioridad | K3: 45782 | L3: 45828
B4: Crítica | D4: 3 | F4: Finanzas | G4: 33 | H4: 69 | J4: En proceso | K4: 5 | L4: 25
B5: Alta | C5: 14 | D5: 91 | F5: Integración Alm. SGA | G5: 5 | H5: 9 | J5: Parada por MP | L5: 12
B6: Media | C6: 18 | D6: 43 | F6: O2C - Order to cash | G6: 22 | H6: 51 | J6: Solucionada | L6: 50
B7: Baja | C7: 47 | D7: 46 | F7: P2P – Procure to pay | G7: 19 | H7: 49 | J7: Entregada | L7: 7
B8: Total general | C8: =SUM(C4:C7) -> 79 | D8: =SUM(D4:D7) -> 183 | F8: IT | H8: 1 | J8: Pte Info MP | L8: 18
F9: Gestión | H9: 4 | J9: Descartada | L9: 2
F10: Total | G10: 79 | H10: =SUM(H4:H9) -> 183 | J10: Nueva | L10: 15
J11: Abierta | K11: 74 | L11: 51
J12: Duplicada | L12: 2
J13: Pte de Pruebas MP | L13: 1
J14: Total general | K14: =SUM(K4:K13) -> 79 | L14: =SUM(L4:L13) -> 183

Sheet Incidencias
A8: Cliente | B8: Nº | C8: F. Incid. | D8: Responsable Cliente | E8: TIPO | F8: Tipo según ALTIM | G8: Descripción / Documento | H8: Observaciones | I8: Prioridad | J8: Comentarios | K8: Sistema | L8: Responsable Altim | M8: Estado | N8: F.Entrega | O8: F. Cierre Prevista | P8: COMENTARIOS FINALES CONSULTOR | Q8: Responsable
B9: EUR0001 | C9: 46035 | D9: Paula | E9: Petición | F9: Evolutivo | G9: Comunicación desde SAP a Aceuro las modificaciones manuales de factura proveedor | H9: Se construye integración de vuelta de SAP a Aceuro con las modificaciones | I9: Media | J9: Integración no contemplada en el alcance del proyecto | L9: Daniel CH. | M9: En proceso | O9: 46037 | P9: En proceso de construcción
B10: EUR0002 | C10: 46035 | D10: Paula | E10: Incidencia | F10: Incidencia | G10: Debe aparecer el campo Expediente en la nueva app de Gestión de Ordenes de Compra | I10: Media | J10: Faltaba una order deWorkbench por subir que aplicaba el cambio | L10: Miguel E. | M10: 3Entregada | N10: 46038 | O10: 46037
B11: EUR0003 | C11: 46034 | D11: Paula | E11: Incidencia | F11: Incidencia | G11: No aparece el campo del prescriptor en la pantalla de la nueva aplicación 'Gestión de pedido de cliente v2' | I11: Baja | J11: Disponible para probar TEST | L11: Paco G. | M11: 3Entregada | O11: 46038
B12: EUR0004 | C12: 46034 | D12: Marisa | E12: Incidencia | F12: Incidencia | G12: No sale el PDF de factura de anulación (documento S1) | I12: Media | J12: Disponible para probar en TEST | L12: Gloria B. | M12: 3Entregada | O12: 46038
B13: EUR0005 | C13: 46034 | D13: Yolanda | E13: Petición | F13: Consulta | G13: El documento de anticipo (FAZ) tiene el Debe/Haber al revés / no se entiende dicho documento | I13: Alta | J13: Explicaciones en correo de Ricardo 'EUROVAL: UATs Globales - Ventas'. Amal puede reforzar dicha explicación a petición o futuras sesiones | L13: Amal H. | M13: 1En proceso
B14: EUR0006 | C14: 46034 | D14: Marisa | E14: Incidencia | F14: Incidencia | G14: El importe del anticipo enviado por la integración no se corresponde con el que aparece en SAP | H14: Se envían 242€ de provisión y en SAP aparecen 180€. | I14: Alta | J14: Corregido y disponible en TEST | L14: Jose Miguel J. | M14: 3Entregada | O14: 46041
B15: EUR0007 | C15: 46034 | D15: Marisa | E15: Incidencia | F15: Incidencia | G15: No se vuelca correctamente la liquidación del anticipo en la factura final del cliente (documento F2) | I15: Alta | J15: Corregido y disponible en TEST | L15: Jose Miguel J. | M15: 3Entregada | O15: 46041
B16: EUR0008 | C16: 46034 | D16: Yolanda | E16: Petición | F16: Petición | G16: Se debe volcar la cuenta de ingreso de la provisión de fondos en la integración hacia SAP, de forma que ayude a EUROVAL a localizar de manera ágil que extractos se corresponden con qué anticipos a la hora de conciliar | I16: Alta | J16: Integración ampliada para contemplar la cuenta de ingreso de provisión. Disponible en TEST | L16: Jose Miguel J. | M16: 3Entregada | O16: 46042
B17: EUR0009 | C17: 46034 | D17: Manuel | E17: Incidencia | F17: Incidencia | G17: No se está aplicando la reversión de la provisión de ingreso en el flujo de ventas. | I17: Alta | J17: Corregido y disponible en TEST | L17: Ricardo M. | M17: 3Entregada | O17: 46042
B18: EUR0010 | C18: 46031 | D18: Manuel | E18: Petición | F18: Petición | G18: Proceso de contabilización de provisiones de gastos financieros | I18: Media | J18: Respuesta a la consulta en correo: Altim_Euroval: Pendientes sesión UATs Finanzas | L18: Amal H. | M18: 3Entregada | O18: 46045
B19: EUR0011 | C19: 46031 | D19: Manuel | E19: Petición | F19: Petición | G19: Generación de documentos de comenpensación | I19: Media | J19: Respuesta a la consulta en correo: Altim_Euroval: Pendientes sesión UATs Finanzas | L19: Amal H. | M19: 3Entregada | O19: 46045
B20: EUR0012 | C20: 46038 | D20: Manuel | E20: Petición | F20: Consulta | G20: Agregar campo "tercero" en informes de centros de coste, centros de beneficio y segmentos de mercado. Actualmente, a finanzas, ese campo llega como "texto posición". | H20: La solución pasa por crear una CDS | I20: Media | J20: No es posible en informes estándar añadir campos adicionales. Se tiene que ver si es posible la derivación a un campo vacío. | L20: Eneko C. | M20: 1En proceso | O20: 46050 | P20: Analizando Posibilidades
B21: EUR0013 | C21: 46038 | D21: Alberto | E21: Petición | F21: Consulta | G21: Agregar más campos en la parte superior de los informes de control de gestión | H21: La solución pasa por crear una CDS | I21: Media | J21: No es posible añadir columnas adicionales en informes estándar. | L21: Eneko C. | M21: 1En proceso | O21: 46050 | P21: Analizando posibilidades
B22: EUR0014 | C22: 46049 | D22: Marisa | E22: Incidencia | F22: Incidencia | G22: La liquidación del anticipo no se reparte en la factura final F2 cuando el cálculo del pedido es de tarifa | I22: Alta | L22: Jose Miguel J. | M22: 1En proceso | O22: 46052
B23: EUR0015 | C23: 46044 | D23: Yolanda | E23: Petición | F23: Petición | G23: Se deben añadir dos campos nuevos en la integración de provisiones: Número único del TPV y vía de pago | I23: Alta | L23: Jose Miguel J. | M23: 3Entregada | O23: 46051
B24: EUR0016 | C24: 46044 | D24: Manuel | E24: Petición | F24: Evolutivo | G24: Se necesita almacenar en la factura de compras la referencia de la factura del tasador cuando es emitida por dicha persona | I24: Alta | J24: Se hará el flujo natural de crear factura de compra con su correspondiente apunte contable | L24: Miguel E. | M24: 1En proceso

Sheet Hoja1
A1: soporte diario en finanzas
A2: Tarifa mas descuento de Leandro
A3: Devolucion Portugal
A4: Voucher
A5: Factura de Portugal
A6: Correccion de la factura para el voucher
A7: PDF hay que hacer algún ajuste

Sheet Comite
A1: Nº | B1: Respon MP | C1: TIPO | D1: Módulo | E1: Descripción / Documento | F1: Prioridad | G1: Estado | H1: F.Entrega | I1: Comentarios 02/06/2025 | J1: Tarea | K1: Responsable
A2: MP-0001 | B2: Isabel, Felipe | C2: Proyecto | D2: Finanzas | E2: Cierre contable 2024 - Extraccion de Información | F2: Alta | G2: Entregada | H2: 45802 | I2: Entregado todo lo requerido | J2: Confirmar para cerrar | K2: MP
A3: MP-00011 | B3: Isabel, Felipe | C3: Proyecto | D3: Finanzas | E3: Cierre contable 2024 - Manipulacion de ficheros para cargar en navision de información extraida | F3: Alta | G3: Entregada | H3: 45810 | I3: Transformado todos los fichero requeridos
A4: MP-00012 | B4: Isabel, Felipe | C4: Proyecto | D4: Finanzas | E4: Cierre contable 2024 - Información SII | F4: Alta | G4: Entregada | H4: 45808 | I4: Extraida la información solicitada y cruzada con el SII
A5: MP-0002 | B5: Isabel | C5: Evolutivo | D5: P2P | E5: Contabilización de costes indirectos en las compras de importación, flete, arancelario etc | F5: Alta | G5: Parada por MP | H5: 45838 | I5: Se ha priorizado otra incidencia
A6: MP-0003 | B6: Isabel | C6: Evolutivo | D6: Finanzas | E6: Meridiano Palaciano no tiene IVA repercutido 23% Soportado | F6: Alta | G6: Pte de Pruebas MP | H6: 45806 | I6: Pendiente de prueba por parte de MP | J6: Pendiente de prueba por parte de MP | K6: MP
A7: MP-0004 | B7: Felipe | C7: Evolutivo | D7: Finanzas | E7: CUENTA 5201100002. Configuración de póliza de crédito de los bancos. | F7: Alta | G7: En proceso | H7: 45811 | I7: Pte de probar por Altim | J7: Pte de probar | K7: Altim
A8: MP-0006 | B8: Isabel | C8: Incidencia | D8: Finanzas | E8: Errores en el proceso de cobro por pagaré | F8: Alta | G8: Cerrada | H8: 45808 | I8: Analizado proceso | J8: Confirmar el cierre | K8: MP
A9: MP-00061 | B9: Isabel | C9: Incidencia | D9: Finanzas | E9: Se intenta buscar una vía para que se pueda automatizar el proceso- Configuracion y pruebas | F9: Alta | G9: Cerrada | H9: 45808 | I9: Configurada propuesta de solución
A10: MP-00062 | B10: Isabel | C10: Petición | D10: Finanzas | E10: Se intenta buscar una vía para que se pueda automatizar el proceso- Formacion y Manual | F10: Alta | G10: Entregada | H10: 45807 | I10: Manual de propuesta de solución | J10: Confirmar el cierre | K10: MP
A11: MP-0007 | B11: Isabel | C11: Evolutivo | D11: Finanzas | E11: Error listado/libro facturas emitidas y recibidas | F11: Alta | G11: Entregada | H11: 45803 | I11: Se facilita informe y la manera de ejecutarlo
A12: MP-00071 | B12: Isabel | C12: Evolutivo | D12: Finanzas | E12: Extraccion documentos con II NT | F12: Alta | G12: Cerrada | H12: 45796 | I12: Se extrae la información y se facilita al usuario
A13: MP-00072 | B13: Isabel | C13: Evolutivo | D13: Finanzas | E13: Se requiere extraer el listado de proveedores y clientes para verificar cuales no tienen NIF o el NIF en campo 2 y 3 necesario de copiar en NIF1 Enviar listado | F13: Baja | G13: Entregada | H13: 45810 | I13: Se extre la información y se facilita al usuario | J13: Confirmar el cierre | K13: MP
A14: MP-0008 | B14: Isabel | C14: Consulta | D14: Finanzas | E14: Problemas sacar informe financieros oficiales | F14: Alta | G14: Entregada | H14: 45810 | I14: Se facilita informe y la manera de ejecutarlo, crendo layout según requerimientos
A15: MP-0009 | B15: Felipe | C15: Incidencia | D15: Finanzas | E15: Problemas en facturaciones por errores en los datos maestros de interlocutores. | F15: Media | G15: Cerrada | H15: 45810 | I15: No se identificar ningún error el usuario nos indica que lo cerremos
A16: MP-0010 | B16: Isabel | C16: Evolutivo | D16: Integración | E16: Con el intercompany actual, Meridiano Palaciano no tiene su proceso de devolución. No hay abono ni factura rectificativa de Portugal. | F16: Alta | G16: Pte de Pruebas MP | H16: 45810 | I16: Se ejecuta el proceso y se enseña pero se identifica mas GAPS
A17: MP-00101 | B17: Isabel | C17: Evolutivo | D17: Finanzas | E17: Auditar la determianción de cuentas de aprovisionamiento | F17: Alta | G17: Entregada | H17: 45810 | I17: Se realiza una reunión de trabajo donde se identifican muchos errores de configuración y DM
A18: MP-0012 | B18: Isabel | C18: Evolutivo | D18: P2P | E18: Factura de venta/ Factura rectificativa/Nota de crédito - Formato de las facturas - Contenido comercial - Configuración fiscal Formulario de venttas | F18: Alta | G18: En proceso | H18: 45818 | I18: Formulario de ventas planificado poner pte de MP el 03/06 | J18: Entregar a MP para probar | K18: Altim
A19: MP-0013 | B19: Isabel | C19: Incidencia | D19: O2C | E19: Otras funciones de facturas de venta | F19: Media | G19: Parada por MP | H19: 45811 | I19: Retraso por no haber recurso de ventas
A20: MP-0016 | B20: Felipe | C20: Evolutivo | D20: Finanzas | E20: La app "Gestión de partidas deudor", queremos que aparece información de los comerciales / vendedores, para distinguir diferente forma de pago | F20: Alta | G20: Descartada | H20: 45810 | I20: Se para, , actualmente no es viable técnicament.
A21: MP-0034 | B21: Lu WANG | C21: Incidencia | D21: Finanzas | E21: Facturas / Nota de crédito mal recargo equivalencia | F21: Alta | G21: Cerrada | H21: 45796 | I21: Se analiza y se explica el proceso porque se calcula correctamente
A22: MP-0035 | B22: Lu WANG | C22: Proyecto | D22: Integración | E22: No hay una sincronización entre SGA y SAP: 1.SGA cuando hace la entrega, viaja a SAP, hace el picking y viaja a SAP, hace la salida y viaja a SAP y en SAP no contabiliza por motivos desconocidos. 2. Los almacenes que hay en SGA no coinciden con los que hay en SAP (no se quiso replicarlos). Es imprescindible definir la arquitectura necesaria para que SGA pueda llevar la trazabilidad deseada. 3. Cuando cambia unidad de medida en SAP, no se cambia en el CRM. 4. Cuando se registra el picking y se pasa la entrega a SAP, la API es muy lenta 5. Todo lo que tiene que ver con estados, modificación de un pedido, etc. no comunica (Problema de API). Se desconoce cómo cerrar Pedidos de venta que tienen entregas parciales: tienen mucho stock “colgado”, que aparece como reservado y no es así. Los pedidos de venta que tienen más de 2000 posiciones no entran en SAP desde CRM, parece que SAP no lo permite. El pedido de MM no puede ser más de 9999. | F22: Alta | G22: Parada por MP | H22: 45930 | I22: Nivel funcional parado por priorizacion de otras incidencias de Logística
A23: MP-00351 | B23: Liu Yalu | C23: Proyecto | D23: Integración | E23: Revisión Integración Suite | F23: Alta | G23: En proceso | H23: 45930 | I23: En revisión las funciones que se estan utilizando
A24: MP-0049 | B24: Liu Yalu | C24: Incidencia | D24: O2C | E24: No hay abono ni factura rectificativa de Portugal | F24: Alta | G24: Entregada | H24: 45806 | I24: Entregada el Juevese identificado nuevos GAPS
A25: MP-0054 | B25: Liu Yalu | C25: Incidencia | D25: P2P | E25: Problemas con Subcontratación Expositores | F25: Alta | G25: Parada por MP | H25: 45930 | I25: Para por priorizar Devoluciones
A26: MP-00551 | B26: Liu Yalu | C26: Incidencia | D26: P2P | E26: Manipulación (Carrefour) (Pendiente por despachar) | F26: Media | G26: Entregada | H26: 45972 | I26: Entregada
A27: MP-0061 | B27: lu WANG | C27: Incidencia | D27: O2C | E27: Facturas emitidas con producto sin centro de beneficio asignado | F27: Alta | G27: En proceso | H27: 45930 | I27: Incidencia scerrada y medida preventiva en proceso
A28: MP-00611 | B28: lu WANG | C28: Evolutivo | D28: P2P | E28: Facturas emitidas con producto sin centro de beneficio asignado/ Aplcar a los DM que se ponga obligatorio el CEBE. Extracción de los materiales. | F28: Media | G28: Entregada | H28: 45810 | I28: Se extraen Materiales , pendiente de recibir CeBe de los faltantes | J28: Definir los cebes de los materiales | K28: MP
A29: MP-0074 | B29: Isabel | C29: Incidencia | D29: O2C | E29: INCIDENCIA en las facturas de Ventas no suben al SII, ERROR 1219 | F29: Alta | G29: Cerrada | H29: 45789 | I29: Se analiza la incidencia y se soluciona
A30: MP-0079 | B30: Susana | C30: Evolutivo | D30: Finanzas | E30: INCIDENCIA EN LAS CUIENTAS DE MAYOR 4109000001/4109000002 Y 4109000003 | F30: Alta | G30: Cerrada | H30: 45790 | I30: Subida las correcciones a producción
A31: MP-0081 | B31: Susana | C31: Incidencia | D31: Finanzas | E31: INCIDENCIA EN EL LIBRO DE CAJA | F31: Media | G31: Cerrada | H31: 45810 | I31: Subida las correcciones a producción
A32: MP-0084 | B32: Susana, Ana | C32: Evolutivo | D32: Finanzas | E32: Necesitamos que todas las cuentas se puedan contabilizar de forma manual. | F32: Media | G32: Pte Info MP | H32: 45838 | I32: Realizada correcciones pte de validación MP | J32: Pte de validación | K32: MP
A33: MP-0085 | B33: Susana, Ana | C33: Evolutivo | D33: Finanzas | E33: Que todas las cuentas del grupo 6 y grupo 7 se puedan contabilizar sin que tenga un indicador de impuesto Entonces por favor del grupo 7 solo habilitarme sin que tenga el indicador de impuesto las cuentas 76- y de gastos quiero todas menos las 6000. Extraccion de información | F33: Media | G33: Entregada | H33: 45807 | I33: Realizada
A34: MP-00851 | B34: Susana, Ana | C34: Evolutivo | D34: Finanzas | E34: Que todas las cuentas del grupo 6 y grupo 7 se puedan contabilizar sin que tenga un indicador de impuesto Entonces por favor del grupo 7 solo habilitarme sin que tenga el indicador de impuesto las cuentas 76- y de gastos quiero todas menos las 6000. Cambio en la configuración | F34: Media | G34: Entregada | H34: 45807 | I34: Realizada correcciones pte de validación MP | J34: Pte de validación | K34: MP
A35: MP-0089 | B35: Susana, Ana | C35: Evolutivo | D35: Finanzas | E35: Queremos crear nuevas cuentas de visa o de gasto, etc… y no podemos hacerlo ninguna de las contables. Por favor enseñárselo bien a los que tengan acceso para no tener problemas de este tipo. Poder contabilizar de forma manual, sin indicador y que estén asignadas | F35: Media | G35: En proceso | H35: 45930 | I35: Pendiente de confirmar requerimientos | J35: Pendiente confirmación | K35: Altim/MP
A36: MP-0090 | B36: Susana, Ana | C36: Evolutivo | D36: Finanzas | E36: Por último, por favor cerrarme los periodos contables y enseñarnos porque transacción podemos abrir y cerrarlos porque nos podemos confundir y contabilizar facturas en fechas que no queremos | F36: Media | G36: Pte de Pruebas MP | H36: 45805 | I36: Enviado a MP, pte de confirmar que esta hecho | J36: Pte de validación | K36: MP
A37: MP-0092 | B37: Susana, Ana | C37: Evolutivo | D37: Finanzas | E37: necesario implementar una validación donde la la fecha de contabilización sea igual o mayor a la fecha del pedido. | F37: Media | G37: En proceso | H37: 45810 | I37: Verificanco viabilidad | J37: Verificanco viabilidad | K37: Altim
A38: MP-0095 | B38: Lu WANG | C38: Formación | D38: Integración | E38: Fomación de arquitectura de sistemas de Private cloud S4 HANA | F38: Media | G38: Cerrada | H38: 45930 | I38: Realizado
A39: MP-0100 | B39: lu WANG | C39: Evolutivo | D39: P2P | E39: Formación Interco | F39: Alta | G39: Cerrada | H39: 45807 | I39: Realizado
A40: MP-0101 | B40: lu WANG | C40: Consulta | D40: O2C | E40: El destinatario de factura puede ser un autonomo y el cliente una empresa | F40: Alta | G40: Entregada | H40: 45799 | I40: Entregado.
...

Sheet Horas
A1: Incidencia | B1: Horas | C1: Mes
A2: MP-0000 | B2: 8 | C2: Mayo | D2: =VLOOKUP(A:A,Incidencias!B:B,1,FALSE) -> #N/A
A3: MP-0000 | B3: 8 | C3: Mayo | D3: =VLOOKUP(A:A,Incidencias!B:B,1,FALSE) -> #N/A
A4: MP-0000 | B4: 8 | C4: Mayo | D4: =VLOOKUP(A:A,Incidencias!B:B,1,FALSE) -> #N/A
A5: MP-0000 | B5: 6.5 | C5: Mayo | D5: =VLOOKUP(A:A,Incidencias!B:B,1,FALSE) -> #N/A
A6: MP-0000 | B6: 1.5 | C6: Mayo | D6: =VLOOKUP(A:A,Incidencias!B:B,1,FALSE) -> #N/A
A7: MP-0000 | B7: 6.5 | C7: Mayo | D7: =VLOOKUP(A:A,Incidencias!B:B,1,FALSE) -> #N/A
A8: MP-0000 | B8: 1.5 | C8: Mayo | D8: =VLOOKUP(A:A,Incidencias!B:B,1,FALSE) -> #N/A
A9: MP-0000 | B9: 1.5 | C9: Mayo | D9: =VLOOKUP(A:A,Incidencias!B:B,1,FALSE) -> #N/A
A10: MP-0000 | B10: 2.5 | C10: Mayo | D10: =VLOOKUP(A:A,Incidencias!B:B,1,FALSE) -> #N/A
A11: MP-0000 | B11: 5.5 | C11: Mayo | D11: =VLOOKUP(A:A,Incidencias!B:B,1,FALSE) -> #N/A
A12: MP-0000 | B12: 3 | C12: Mayo | D12: =VLOOKUP(A:A,Incidencias!B:B,1,FALSE) -> #N/A
A13: MP-0000 | B13: 3 | C13: Mayo | D13: =VLOOKUP(A:A,Incidencias!B:B,1,FALSE) -> #N/A
... A347: MP-01119 | B347: 3 | C347: Junio | D347: =VLOOKUP(A:A,Incidencias!B:B,1,FALSE) -> #N/A
A348: MP-0024 | B348: 7.5 | C348: Junio | D348: =VLOOKUP(A:A,Incidencias!B:B,1,FALSE) -> #N/A | H348: BI
A349: MP-01119 | B349: 0.5 | C349: Junio | D349: =VLOOKUP(A:A,Incidencias!B:B,1,FALSE) -> #N/A
A350: MP-0087 | B350: 2.5 | C350: Junio | D350: =VLOOKUP(A:A,Incidencias!B:B,1,FALSE) -> #N/A
A351: MP-0073 | B351: 2 | C351: Junio | D351: =VLOOKUP(A:A,Incidencias!B:B,1,FALSE) -> #N/A
A352: MP-0097 | B352: 2 | C352: Junio | D352: =VLOOKUP(A:A,Incidencias!B:B,1,FALSE) -> #N/A
A353: MP-0024 | B353: 1 | C353: Junio | D353: =VLOOKUP(A:A,Incidencias!B:B,1,FALSE) -> #N/A | H353: II
A354: MP-01119 | B354: 0.5 | C354: Junio | D354: =VLOOKUP(A:A,Incidencias!B:B,1,FALSE) -> #N/A
A355: MP-0012 | B355: 1.5 | C355: Junio | D355: =VLOOKUP(A:A,Incidencias!B:B,1,FALSE) -> #N/A
A356: MP-0012 | B356: 0.5 | C356: Junio | D356: =VLOOKUP(A:A,Incidencias!B:B,1,FALSE) -> #N/A
A357: Sumariza | B357: 2 | C357: Junio | D357: =VLOOKUP(A:A,Incidencias!B:B,1,FALSE) -> #N/A
A358: MP-0012 | B358: 2 | C358: Junio | D358: =VLOOKUP(A:A,Incidencias!B:B,1,FALSE) -> #N/A
A359: MP-0115 | B359: 4 | C359: Junio | D359: =VLOOKUP(A:A,Incidencias!B:B,1,FALSE) -> #N/A
A360: MP-0115 | B360: 4 | C360: Junio | D360: =VLOOKUP(A:A,Incidencias!B:B,1,FALSE) -> #N/A
A361: MP-0104 | B361: 4.5 | C361: Junio | D361: =VLOOKUP(A:A,Incidencias!B:B,1,FALSE) -> #N/A
A362: MP-0104 | B362: 3.5 | C362: Junio | D362: =VLOOKUP(A:A,Incidencias!B:B,1,FALSE) -> #N/A
A363: MP-0117 | B363: 5 | C363: Junio | D363: =VLOOKUP(A:A,Incidencias!B:B,1,FALSE) -> #N/A
A364: MP-0117 | B364: 3 | C364: Junio | D364: =VLOOKUP(A:A,Incidencias!B:B,1,FALSE) -> #N/A
A365: MP-0026 | B365: 4.5 | C365: Junio | D365: =VLOOKUP(A:A,Incidencias!B:B,1,FALSE) -> #N/A
... A521: MP-0143 | B521: 8 | C521: Junio | D521: =VLOOKUP(A:A,Incidencias!B:B,1,FALSE) -> #N/A

Sheet Plan
A1: PLANIFICADO HASTA 30/06 | E1: SIN PLANIFICACIÓN
A3: TIPO | B3: (en blanco) | E3: TIPO | F3: (en blanco)
A5: Responsable Altim | B5: Estado | C5: Nº | E5: Responsable Altim | F5: Estado | G5: Nº
A6: (en blanco) | B6: (en blanco) | C6: (en blanco) | E6: (en blanco) | F6: (en blanco) | G6: (en blanco)

Sheet CdM
A1: Bloque | B1: (en blanco)
A2: Tipo según ALTIM | B2: (en blanco)
A4: Etiquetas de fila | B4: Cuenta de Estado
A5: (en blanco)
A6: Total general
A29: TIPO | B29: (en blanco)
A31: Prioridad | B31: Cuenta de Nº
A32: (en blanco)
A33: Total general
A39: TIPO | B39: (en blanco)
A41: Etiquetas de fila | B41: Cuenta de Nº
A42: (en blanco)
A43: Total general
A64: TIPO | B64: (en blanco)
A65: Estado | B65: (en blanco)
A67: Etiquetas de fila | B67: Cuenta de Nº
A68: (en blanco)
A69: Total general
A80: TIPO | B80: (Todas)
A81: Estado | B81: (Todas)
A83: Etiquetas de fila | B83: Cuenta de Nº
A84: Finanzas | B84: 78
A85: P2P | B85: 49
A86: O2C | B86: 53
A87: Integración | B87: 9
A88: IT | B88: 1
A89: Gestión | B89: 6
A90: OTC | B90: 3
A91: PTP | B91: 5
A92: Total general | B92: 204
A100: Número incidencia | B100: Mes apertura | C100: Mes resolución | D100: Mes cierre | F100: Mes | G100: Abiertas | H100: Realizadas | I100: Cerradas | J100: Entregadas | L100: Abiertas | M100: Entregadas | N100: Cerradas | P100: Número incidencia | Q100: Semana apertura | R100: Semana resolución
A101: =Incidencias!B211 -> 0 | B101: =IF(Incidencias!E211="Mejora",0,MONTH(Incidencias!C211)) -> 1 | C101: =IF(Incidencias!M211="Entregada",MONTH(Incidencias!N211),0) -> 0 | D101: =IF(Incidencias!M211="Cerrada",MONTH(Incidencias!O211),0) -> 0 | F101: 4 | G101: =COUNTIF(B$100:B$409,$F101) -> 0 | H101: =COUNTIF(C$100:C$409,$F101) -> 0 | I101: =COUNTIF(D$100:D$409,$F101) -> 0 | J101: =H101+I101 -> 0 | K101: 44287 | L101: =G101 -> 0 | M101: =J101 -> 0 | N101: =I101 -> 0 | P101: =Incidencias!B211 -> 0 | Q101: =IF(Incidencias!E211="MEJORA",0,WEEKNUM(Incidencias!C211)) -> 0 | R101: =WEEKNUM(Incidencias!N211) -> 0
A102: =Incidencias!#REF! -> #REF! | B102: =IF(Incidencias!#REF!="Mejora",0,MONTH(Incidencias!#REF!)) -> #REF! | C102: =IF(Incidencias!#REF!="Entregada",MONTH(Incidencias!#REF!),0) -> #REF! | D102: =IF(Incidencias!#REF!="Cerrada",MONTH(Incidencias!#REF!),0) -> #REF! | F102: 5 | G102: =COUNTIF(B$100:B$409,$F102) -> 0 | H102: =COUNTIF(C$100:C$409,$F102) -> 0 | I102: =COUNTIF(D$100:D$409,$F102) -> 0 | J102: =H102+I102 -> 0 | K102: 44317 | L102: =L101+G102 -> 0 | M102: =J102+M101 -> 0 | N102: =N101+I102 -> 0 | P102: =Incidencias!#REF! -> #REF! | Q102: =IF(Incidencias!#REF!="MEJORA",0,WEEKNUM(Incidencias!#REF!)) -> #REF! | R102: =WEEKNUM(Incidencias!#REF!) -> #REF!
A103: =Incidencias!B9 -> EUR0001 | B103: =IF(Incidencias!E9="Mejora",0,MONTH(Incidencias!C9)) -> 1 | C103: =IF(Incidencias!M9="Entregada",MONTH(Incidencias!N9),0) -> 0 | D103: =IF(Incidencias!M9="Cerrada",MONTH(Incidencias!O9),0) -> 0 | F103: 6 | G103: =COUNTIF(B$100:B$409,$F103) -> 0 | H103: =COUNTIF(C$100:C$409,$F103) -> 0 | I103: =COUNTIF(D$100:D$409,$F103) -> 0 | J103: =H103+I103 -> 0 | K103: 44348 | L103: =L102+G103 -> 0 | M103: =J103+M102 -> 0 | N103: =N102+I103 -> 0 | P103: =Incidencias!B9 -> EUR0001 | Q103: =IF(Incidencias!E9="MEJORA",0,WEEKNUM(Incidencias!C9)) -> 3 | R103: =WEEKNUM(Incidencias!N9) -> 0
A104: =Incidencias!B10 -> EUR0002 | B104: =IF(Incidencias!E10="Mejora",0,MONTH(Incidencias!C10)) -> 1 | C104: =IF(Incidencias!M10="Entregada",MONTH(Incidencias!N10),0) -> 0 | D104: =IF(Incidencias!M10="Cerrada",MONTH(Incidencias!O10),0) -> 0 | F104: 7 | G104: =COUNTIF(B$100:B$409,$F104) -> 0 | H104: =COUNTIF(C$100:C$409,$F104) -> 0 | I104: =COUNTIF(D$100:D$409,$F104) -> 0 | J104: =H104+I104 -> 0 | K104: 44378 | L104: =L103+G104 -> 0 | M104: =J104+M103 -> 0 | N104: =N103+I104 -> 0 | P104: =Incidencias!B10 -> EUR0002 | Q104: =IF(Incidencias!E10="MEJORA",0,WEEKNUM(Incidencias!C10)) -> 3 | R104: =WEEKNUM(Incidencias!N10) -> 3
A105: =Incidencias!B13 -> EUR0005 | B105: =IF(Incidencias!E13="Mejora",0,MONTH(Incidencias!C13)) -> 1 | C105: =IF(Incidencias!M13="Entregada",MONTH(Incidencias!N13),0) -> 0 | D105: =IF(Incidencias!M13="Cerrada",MONTH(Incidencias!O13),0) -> 0 | F105: 8 | G105: =COUNTIF(B$100:B$409,$F105) -> 0 | H105: =COUNTIF(C$100:C$409,$F105) -> 0 | I105: =COUNTIF(D$100:D$409,$F105) -> 0 | J105: =H105+I105 -> 0 | K105: 44409 | L105: =L104+G105 -> 0 | M105: =J105+M104 -> 0 | N105: =N104+I105 -> 0 | P105: =Incidencias!B13 -> EUR0005 | Q105: =IF(Incidencias!E13="MEJORA",0,WEEKNUM(Incidencias!C13)) -> 3 | R105: =WEEKNUM(Incidencias!N13) -> 0
A106: =Incidencias!B14 -> EUR0006 | B106: =IF(Incidencias!E14="Mejora",0,MONTH(Incidencias!C14)) -> 1 | C106: =IF(Incidencias!M14="Entregada",MONTH(Incidencias!N14),0) -> 0 | D106: =IF(Incidencias!M14="Cerrada",MONTH(Incidencias!O14),0) -> 0 | F106: 9 | G106: =COUNTIF(B$100:B$420,$F106) -> 0 | H106: =COUNTIF(C$100:C$420,$F106) -> 0 | I106: =COUNTIF(D$100:D$420,$F106) -> 0 | J106: =H106+I106 -> 0 | K106: 44440 | L106: =L105+G106 -> 0 | M106: =J106+M105 -> 0 | N106: =N105+I106 -> 0 | P106: =Incidencias!B14 -> EUR0006 | Q106: =IF(Incidencias!E14="MEJORA",0,WEEKNUM(Incidencias!C14)) -> 3 | R106: =WEEKNUM(Incidencias!N14) -> 0
A107: =Incidencias!B15 -> EUR0007 | B107: =IF(Incidencias!E15="Mejora",0,MONTH(Incidencias!C15)) -> 1 | C107: =IF(Incidencias!M15="Entregada",MONTH(Incidencias!N15),0) -> 0 | D107: =IF(Incidencias!M15="Cerrada",MONTH(Incidencias!O15),0) -> 0 | P107: =Incidencias!B15 -> EUR0007 | Q107: =IF(Incidencias!E15="MEJORA",0,WEEKNUM(Incidencias!C15)) -> 3 | R107: =WEEKNUM(Incidencias!N15) -> 0
A108: =Incidencias!B16 -> EUR0008 | B108: =IF(Incidencias!E16="Mejora",0,MONTH(Incidencias!C16)) -> 1 | C108: =IF(Incidencias!M16="Entregada",MONTH(Incidencias!N16),0) -> 0 | D108: =IF(Incidencias!M16="Cerrada",MONTH(Incidencias!O16),0) -> 0 | P108: =Incidencias!B16 -> EUR0008 | Q108: =IF(Incidencias!E16="MEJORA",0,WEEKNUM(Incidencias!C16)) -> 3 | R108: =WEEKNUM(Incidencias!N16) -> 0
A109: =Incidencias!B17 -> EUR0009 | B109: =IF(Incidencias!E17="Mejora",0,MONTH(Incidencias!C17)) -> 1 | C109: =IF(Incidencias!M17="Entregada",MONTH(Incidencias!N17),0) -> 0 | D109: =IF(Incidencias!M17="Cerrada",MONTH(Incidencias!O17),0) -> 0 | P109: =Incidencias!B17 -> EUR0009 | Q109: =IF(Incidencias!E17="MEJORA",0,WEEKNUM(Incidencias!C17)) -> 3 | R109: =WEEKNUM(Incidencias!N17) -> 0
...

Sheet CdM2
A1: Número incidencia | B1: Tipo | C1: Estado | D1: Bloqueante | E1: Error usuario | H1: Incidencias totales | I1: =COUNTIF(Tabla2[[#All],[Tipo]],"Incidencia") -> 80
A2: =Incidencias!B211 -> 0 | B2: =IF(Incidencias!E211="Mejora","Mejora","Incidencia") -> Incidencia | C2: =IF(Incidencias!E211="Mejora","NA",IF(OR(Incidencias!M211="Abierta",Incidencias!M211="En proceso",Incidencias!M211="Info cliente")=TRUE,"En curso",IF(Incidencias!M211="Descartada","Descartada","Entregada"))) -> Entregada | D2: =IF(C2="En curso", IF(Incidencias!#REF!="Sí","Bloqueante", IF(Incidencias!#REF!="No","No bloqueante","NA")),"NA") -> NA | E2: =IF(C2="En curso", IF(Incidencias!#REF!="Usuario","Usuario", IF(Incidencias!#REF!="Proceso","Proceso","NA")),"NA") -> NA | H2: Incidencias en curso | I2: =COUNTIF(Tabla2[[#All],[Estado]],"En curso") -> 0 | J2: =I2/I1 -> 0
A3: =Incidencias!#REF! -> #REF! | B3: =IF(Incidencias!E13="Mejora","Mejora","Incidencia") -> Incidencia | C3: =IF(Incidencias!E13="Mejora","NA",IF(OR(Incidencias!M13="Abierta",Incidencias!M13="En proceso",Incidencias!M13="Info cliente")=TRUE,"En curso",IF(Incidencias!M13="Descartada","Descartada","Entregada"))) -> Entregada | D3: =IF(C3="En curso", IF(Incidencias!#REF!="Sí","Bloqueante", IF(Incidencias!#REF!="No","No bloqueante","NA")),"NA") -> NA | E3: =IF(C3="En curso", IF(Incidencias!#REF!="Usuario","Usuario", IF(Incidencias!#REF!="Proceso","Proceso","NA")),"NA") -> NA | H3: Incidencias bloqueantes | I3: =COUNTIF(Tabla2[[#All],[Bloqueante]],"Bloqueante") -> 1 | J3: =I3/I2 -> #DIV/0!
A4: =Incidencias!B9 -> EUR0001 | B4: =IF(Incidencias!E14="Mejora","Mejora","Incidencia") -> Incidencia | C4: =IF(Incidencias!E14="Mejora","NA",IF(OR(Incidencias!M14="Abierta",Incidencias!M14="En proceso",Incidencias!M14="Info cliente")=TRUE,"En curso",IF(Incidencias!M14="Descartada","Descartada","Entregada"))) -> Entregada | D4: =IF(C4="En curso", IF(Incidencias!#REF!="Sí","Bloqueante", IF(Incidencias!#REF!="No","No bloqueante","NA")),"NA") -> NA | E4: =IF(C4="En curso", IF(Incidencias!#REF!="Usuario","Usuario", IF(Incidencias!#REF!="Proceso","Proceso","NA")),"NA") -> NA | H4: Errores de usuario | I4: =COUNTIF(Tabla2[[#All],[Error usuario]],"Usuario") -> 0 | J4: =I4/I2 -> #DIV/0!
A5: =Incidencias!B10 -> EUR0002 | B5: =IF(Incidencias!E15="Mejora","Mejora","Incidencia") -> Incidencia | C5: =IF(Incidencias!E15="Mejora","NA",IF(OR(Incidencias!M15="Abierta",Incidencias!M15="En proceso",Incidencias!M15="Info cliente")=TRUE,"En curso",IF(Incidencias!M15="Descartada","Descartada","Entregada"))) -> Entregada | D5: =IF(C5="En curso", IF(Incidencias!#REF!="Sí","Bloqueante", IF(Incidencias!#REF!="No","No bloqueante","NA")),"NA") -> NA | E5: =IF(C5="En curso", IF(Incidencias!#REF!="Usuario","Usuario", IF(Incidencias!#REF!="Proceso","Proceso","NA")),"NA") -> NA
A6: =Incidencias!B13 -> EUR0005 | B6: =IF(Incidencias!E16="Mejora","Mejora","Incidencia") -> Incidencia | C6: =IF(Incidencias!E16="Mejora","NA",IF(OR(Incidencias!M16="Abierta",Incidencias!M16="En proceso",Incidencias!M16="Info cliente")=TRUE,"En curso",IF(Incidencias!M16="Descartada","Descartada","Entregada"))) -> Entregada | D6: =IF(C6="En curso", IF(Incidencias!#REF!="Sí","Bloqueante", IF(Incidencias!#REF!="No","No bloqueante","NA")),"NA") -> NA | E6: =IF(C6="En curso", IF(Incidencias!#REF!="Usuario","Usuario", IF(Incidencias!#REF!="Proceso","Proceso","NA")),"NA") -> NA
A7: =Incidencias!B14 -> EUR0006 | B7: =IF(Incidencias!E17="Mejora","Mejora","Incidencia") -> Incidencia | C7: =IF(Incidencias!E17="Mejora","NA",IF(OR(Incidencias!M17="Abierta",Incidencias!M17="En proceso",Incidencias!M17="Info cliente")=TRUE,"En curso",IF(Incidencias!M17="Descartada","Descartada","Entregada"))) -> Entregada | D7: =IF(C7="En curso", IF(Incidencias!#REF!="Sí","Bloqueante", IF(Incidencias!#REF!="No","No bloqueante","NA")),"NA") -> NA | E7: =IF(C7="En curso", IF(Incidencias!#REF!="Usuario","Usuario", IF(Incidencias!#REF!="Proceso","Proceso","NA")),"NA") -> NA
A8: =Incidencias!B15 -> EUR0007 | B8: =IF(Incidencias!E21="Mejora","Mejora","Incidencia") -> Incidencia | C8: =IF(Incidencias!E21="Mejora","NA",IF(OR(Incidencias!M21="Abierta",Incidencias!M21="En proceso",Incidencias!M21="Info cliente")=TRUE,"En curso",IF(Incidencias!M21="Descartada","Descartada","Entregada"))) -> Entregada | D8: =IF(C8="En curso", IF(Incidencias!#REF!="Sí","Bloqueante", IF(Incidencias!#REF!="No","No bloqueante","NA")),"NA") -> NA | E8: =IF(C8="En curso", IF(Incidencias!#REF!="Usuario","Usuario", IF(Incidencias!#REF!="Proceso","Proceso","NA")),"NA") -> NA
A9: =Incidencias!B16 -> EUR0008 | B9: =IF(Incidencias!#REF!="Mejora","Mejora","Incidencia") -> #REF! | C9: =IF(Incidencias!#REF!="Mejora","NA",IF(OR(Incidencias!#REF!="Abierta",Incidencias!#REF!="En proceso",Incidencias!#REF!="Info cliente")=TRUE,"En curso",IF(Incidencias!#REF!="Descartada","Descartada","Entregada"))) -> #REF! | D9: =IF(C9="En curso", IF(Incidencias!#REF!="Sí","Bloqueante", IF(Incidencias!#REF!="No","No bloqueante","NA")),"NA") -> #REF! | E9: =IF(C9="En curso", IF(Incidencias!#REF!="Usuario","Usuario", IF(Incidencias!#REF!="Proceso","Proceso","NA")),"NA") -> #REF!
A10: =Incidencias!B17 -> EUR0009 | B10: =IF(Incidencias!E25="Mejora","Mejora","Incidencia") -> Incidencia | C10: =IF(Incidencias!E25="Mejora","NA",IF(OR(Incidencias!M25="Abierta",Incidencias!M25="En proceso",Incidencias!M25="Info cliente")=TRUE,"En curso",IF(Incidencias!M25="Descartada","Descartada","Entregada"))) -> Entregada | D10: =IF(C10="En curso", IF(Incidencias!#REF!="Sí","Bloqueante", IF(Incidencias!#REF!="No","No bloqueante","NA")),"NA") -> NA | E10: =IF(C10="En curso", IF(Incidencias!#REF!="Usuario","Usuario", IF(Incidencias!#REF!="Proceso","Proceso","NA")),"NA") -> NA
A11: =Incidencias!B21 -> EUR0013 | B11: =IF(Incidencias!E26="Mejora","Mejora","Incidencia") -> Incidencia | C11: =IF(Incidencias!E26="Mejora","NA",IF(OR(Incidencias!M26="Abierta",Incidencias!M26="En proceso",Incidencias!M26="Info cliente")=TRUE,"En curso",IF(Incidencias!M26="Descartada","Descartada","Entregada"))) -> Entregada | D11: =IF(C11="En curso", IF(Incidencias!#REF!="Sí","Bloqueante", IF(Incidencias!#REF!="No","No bloqueante","NA")),"NA") -> NA | E11: =IF(C11="En curso", IF(Incidencias!#REF!="Usuario","Usuario", IF(Incidencias!#REF!="Proceso","Proceso","NA")),"NA") -> NA
A12: =Incidencias!B22 -> EUR0014 | B12: =IF(Incidencias!E28="Mejora","Mejora","Incidencia") -> Incidencia | C12: =IF(Incidencias!E28="Mejora","NA",IF(OR(Incidencias!M28="Abierta",Incidencias!M28="En proceso",Incidencias!M28="Info cliente")=TRUE,"En curso",IF(Incidencias!M28="Descartada","Descartada","Entregada"))) -> Entregada | D12: =IF(C12="En curso", IF(Incidencias!#REF!="Sí","Bloqueante", IF(Incidencias!#REF!="No","No bloqueante","NA")),"NA") -> NA | E12: =IF(C12="En curso", IF(Incidencias!#REF!="Usuario","Usuario", IF(Incidencias!#REF!="Proceso","Proceso","NA")),"NA") -> NA
A13: =Incidencias!B23 -> EUR0015 | B13: =IF(Incidencias!E29="Mejora","Mejora","Incidencia") -> Incidencia | C13: =IF(Incidencias!E29="Mejora","NA",IF(OR(Incidencias!M29="Abierta",Incidencias!M29="En proceso",Incidencias!M29="Info cliente")=TRUE,"En curso",IF(Incidencias!M29="Descartada","Descartada","Entregada"))) -> Entregada | D13: =IF(C13="En curso", IF(Incidencias!#REF!="Sí","Bloqueante", IF(Incidencias!#REF!="No","No bloqueante","NA")),"NA") -> NA | E13: =IF(C13="En curso", IF(Incidencias!#REF!="Usuario","Usuario", IF(Incidencias!#REF!="Proceso","Proceso","NA")),"NA") -> NA
A14: =Incidencias!#REF! -> #REF! | B14: =IF(Incidencias!E35="Mejora","Mejora","Incidencia") -> Incidencia | C14: =IF(Incidencias!E35="Mejora","NA",IF(OR(Incidencias!M35="Abierta",Incidencias!M35="En proceso",Incidencias!M35="Info cliente")=TRUE,"En curso",IF(Incidencias!M35="Descartada","Descartada","Entregada"))) -> Entregada | D14: =IF(C14="En curso", IF(Incidencias!#REF!="Sí","Bloqueante", IF(Incidencias!#REF!="No","No bloqueante","NA")),"NA") -> NA | E14: =IF(C14="En curso", IF(Incidencias!#REF!="Usuario","Usuario", IF(Incidencias!#REF!="Proceso","Proceso","NA")),"NA") -> NA
A15: =Incidencias!B25 -> 0 | B15: =IF(Incidencias!E36="Mejora","Mejora","Incidencia") -> Incidencia | C15: =IF(Incidencias!E36="Mejora","NA",IF(OR(Incidencias!M36="Abierta",Incidencias!M36="En proceso",Incidencias!M36="Info cliente")=TRUE,"En curso",IF(Incidencias!M36="Descartada","Descartada","Entregada"))) -> Entregada | D15: =IF(C15="En curso", IF(Incidencias!#REF!="Sí","Bloqueante", IF(Incidencias!#REF!="No","No bloqueante","NA")),"NA") -> NA | E15: =IF(C15="En curso", IF(Incidencias!#REF!="Usuario","Usuario", IF(Incidencias!#REF!="Proceso","Proceso","NA")),"NA") -> NA
A16: =Incidencias!B26 -> 0 | B16: =IF(Incidencias!E39="Mejora","Mejora","Incidencia") -> Incidencia | C16: =IF(Incidencias!E39="Mejora","NA",IF(OR(Incidencias!M39="Abierta",Incidencias!M39="En proceso",Incidencias!M39="Info cliente")=TRUE,"En curso",IF(Incidencias!M39="Descartada","Descartada","Entregada"))) -> Entregada | D16: =IF(C16="En curso", IF(Incidencias!#REF!="Sí","Bloqueante", IF(Incidencias!#REF!="No","No bloqueante","NA")),"NA") -> NA | E16: =IF(C16="En curso", IF(Incidencias!#REF!="Usuario","Usuario", IF(Incidencias!#REF!="Proceso","Proceso","NA")),"NA") -> NA
A17: =Incidencias!B27 -> 0 | B17: =IF(Incidencias!E40="Mejora","Mejora","Incidencia") -> Incidencia | C17: =IF(Incidencias!E40="Mejora","NA",IF(OR(Incidencias!M40="Abierta",Incidencias!M40="En proceso",Incidencias!M40="Info cliente")=TRUE,"En curso",IF(Incidencias!M40="Descartada","Descartada","Entregada"))) -> Entregada | D17: =IF(C17="En curso", IF(Incidencias!#REF!="Sí","Bloqueante", IF(Incidencias!#REF!="No","No bloqueante","NA")),"NA") -> NA | E17: =IF(C17="En curso", IF(Incidencias!#REF!="Usuario","Usuario", IF(Incidencias!#REF!="Proceso","Proceso","NA")),"NA") -> NA
A18: =Incidencias!B28 -> 0 | B18: =IF(Incidencias!E41="Mejora","Mejora","Incidencia") -> Incidencia | C18: =IF(Incidencias!E41="Mejora","NA",IF(OR(Incidencias!M41="Abierta",Incidencias!M41="En proceso",Incidencias!M41="Info cliente")=TRUE,"En curso",IF(Incidencias!M41="Descartada","Descartada","Entregada"))) -> Entregada | D18: =IF(C18="En curso", IF(Incidencias!#REF!="Sí","Bloqueante", IF(Incidencias!#REF!="No","No bloqueante","NA")),"NA") -> NA | E18: =IF(C18="En curso", IF(Incidencias!#REF!="Usuario","Usuario", IF(Incidencias!#REF!="Proceso","Proceso","NA")),"NA") -> NA
A19: =Incidencias!B29 -> 0 | B19: =IF(Incidencias!E43="Mejora","Mejora","Incidencia") -> Incidencia | C19: =IF(Incidencias!E43="Mejora","NA",IF(OR(Incidencias!M43="Abierta",Incidencias!M43="En proceso",Incidencias!M43="Info cliente")=TRUE,"En curso",IF(Incidencias!M43="Descartada","Descartada","Entregada"))) -> Entregada | D19: =IF(C19="En curso", IF(Incidencias!#REF!="Sí","Bloqueante", IF(Incidencias!#REF!="No","No bloqueante","NA")),"NA") -> NA | E19: =IF(C19="En curso", IF(Incidencias!#REF!="Usuario","Usuario", IF(Incidencias!#REF!="Proceso","Proceso","NA")),"NA") -> NA
A20: =Incidencias!B35 -> 0 | B20: =IF(Incidencias!E44="Mejora","Mejora","Incidencia") -> Incidencia | C20: =IF(Incidencias!E44="Mejora","NA",IF(OR(Incidencias!M44="Abierta",Incidencias!M44="En proceso",Incidencias!M44="Info cliente")=TRUE,"En curso",IF(Incidencias!M44="Descartada","Descartada","Entregada"))) -> Entregada | D20: =IF(C20="En curso", IF(Incidencias!#REF!="Sí","Bloqueante", IF(Incidencias!#REF!="No","No bloqueante","NA")),"NA") -> NA | E20: =IF(C20="En curso", IF(Incidencias!#REF!="Usuario","Usuario", IF(Incidencias!#REF!="Proceso","Proceso","NA")),"NA") -> NA
A21: =Incidencias!B36 -> 0 | B21: =IF(Incidencias!E45="Mejora","Mejora","Incidencia") -> Incidencia | C21: =IF(Incidencias!E45="Mejora","NA",IF(OR(Incidencias!M45="Abierta",Incidencias!M45="En proceso",Incidencias!M45="Info cliente")=TRUE,"En curso",IF(Incidencias!M45="Descartada","Descartada","Entregada"))) -> Entregada | D21: =IF(C21="En curso", IF(Incidencias!#REF!="Sí","Bloqueante", IF(Incidencias!#REF!="No","No bloqueante","NA")),"NA") -> NA | E21: =IF(C21="En curso", IF(Incidencias!#REF!="Usuario","Usuario", IF(Incidencias!#REF!="Proceso","Proceso","NA")),"NA") -> NA
A22: =Incidencias!B39 -> 0 | B22: =IF(Incidencias!E46="Mejora","Mejora","Incidencia") -> Incidencia | C22: =IF(Incidencias!E46="Mejora","NA",IF(OR(Incidencias!M46="Abierta",Incidencias!M46="En proceso",Incidencias!M46="Info cliente")=TRUE,"En curso",IF(Incidencias!M46="Descartada","Descartada","Entregada"))) -> Entregada | D22: =IF(C22="En curso", IF(Incidencias!#REF!="Sí","Bloqueante", IF(Incidencias!#REF!="No","No bloqueante","NA")),"NA") -> NA | E22: =IF(C22="En curso", IF(Incidencias!#REF!="Usuario","Usuario", IF(Incidencias!#REF!="Proceso","Proceso","NA")),"NA") -> NA
A23: =Incidencias!B40 -> 0 | B23: =IF(Incidencias!E47="Mejora","Mejora","Incidencia") -> Incidencia | C23: =IF(Incidencias!E47="Mejora","NA",IF(OR(Incidencias!M47="Abierta",Incidencias!M47="En proceso",Incidencias!M47="Info cliente")=TRUE,"En curso",IF(Incidencias!M47="Descartada","Descartada","Entregada"))) -> Entregada | D23: =IF(C23="En curso", IF(Incidencias!#REF!="Sí","Bloqueante", IF(Incidencias!#REF!="No","No bloqueante","NA")),"NA") -> NA | E23: =IF(C23="En curso", IF(Incidencias!#REF!="Usuario","Usuario", IF(Incidencias!#REF!="Proceso","Proceso","NA")),"NA") -> NA
A24: =Incidencias!B41 -> 0 | B24: =IF(Incidencias!E48="Mejora","Mejora","Incidencia") -> Incidencia | C24: =IF(Incidencias!E48="Mejora","NA",IF(OR(Incidencias!M48="Abierta",Incidencias!M48="En proceso",Incidencias!M48="Info cliente")=TRUE,"En curso",IF(Incidencias!M48="Descartada","Descartada","Entregada"))) -> Entregada | D24: =IF(C24="En curso", IF(Incidencias!#REF!="Sí","Bloqueante", IF(Incidencias!#REF!="No","No bloqueante","NA")),"NA") -> NA | E24: =IF(C24="En curso", IF(Incidencias!#REF!="Usuario","Usuario", IF(Incidencias!#REF!="Proceso","Proceso","NA")),"NA") -> NA
A25: =Incidencias!B43 -> 0 | B25: =IF(Incidencias!E49="Mejora","Mejora","Incidencia") -> Incidencia | C25: =IF(Incidencias!E49="Mejora","NA",IF(OR(Incidencias!M49="Abierta",Incidencias!M49="En proceso",Incidencias!M49="Info cliente")=TRUE,"En curso",IF(Incidencias!M49="Descartada","Descartada","Entregada"))) -> Entregada | D25: =IF(C25="En curso", IF(Incidencias!#REF!="Sí","Bloqueante", IF(Incidencias!#REF!="No","No bloqueante","NA")),"NA") -> NA | E25: =IF(C25="En curso", IF(Incidencias!#REF!="Usuario","Usuario", IF(Incidencias!#REF!="Proceso","Proceso","NA")),"NA") -> NA
A26: =Incidencias!B44 -> 0 | B26: =IF(Incidencias!E50="Mejora","Mejora","Incidencia") -> Incidencia | C26: =IF(Incidencias!E50="Mejora","NA",IF(OR(Incidencias!M50="Abierta",Incidencias!M50="En proceso",Incidencias!M50="Info cliente")=TRUE,"En curso",IF(Incidencias!M50="Descartada","Descartada","Entregada"))) -> Entregada | D26: =IF(C26="En curso", IF(Incidencias!#REF!="Sí","Bloqueante", IF(Incidencias!#REF!="No","No bloqueante","NA")),"NA") -> NA | E26: =IF(C26="En curso", IF(Incidencias!#REF!="Usuario","Usuario", IF(Incidencias!#REF!="Proceso","Proceso","NA")),"NA") -> NA
A27: =Incidencias!B45 -> 0 | B27: =IF(Incidencias!E51="Mejora","Mejora","Incidencia") -> Incidencia | C27: =IF(Incidencias!E51="Mejora","NA",IF(OR(Incidencias!M51="Abierta",Incidencias!M51="En proceso",Incidencias!M51="Info cliente")=TRUE,"En curso",IF(Incidencias!M51="Descartada","Descartada","Entregada"))) -> Entregada | D27: =IF(C27="En curso", IF(Incidencias!#REF!="Sí","Bloqueante", IF(Incidencias!#REF!="No","No bloqueante","NA")),"NA") -> NA | E27: =IF(C27="En curso", IF(Incidencias!#REF!="Usuario","Usuario", IF(Incidencias!#REF!="Proceso","Proceso","NA")),"NA") -> NA
A28: =Incidencias!B46 -> 0 | B28: =IF(Incidencias!E52="Mejora","Mejora","Incidencia") -> Incidencia | C28: =IF(Incidencias!E52="Mejora","NA",IF(OR(Incidencias!M52="Abierta",Incidencias!M52="En proceso",Incidencias!M52="Info cliente")=TRUE,"En curso",IF(Incidencias!M52="Descartada","Descartada","Entregada"))) -> Entregada | D28: =IF(C28="En curso", IF(Incidencias!#REF!="Sí","Bloqueante", IF(Incidencias!#REF!="No","No bloqueante","NA")),"NA") -> NA | E28: =IF(C28="En curso", IF(Incidencias!#REF!="Usuario","Usuario", IF(Incidencias!#REF!="Proceso","Proceso","NA")),"NA") -> NA
A29: =Incidencias!B47 -> 0 | B29: =IF(Incidencias!E53="Mejora","Mejora","Incidencia") -> Incidencia | C29: =IF(Incidencias!E53="Mejora","NA",IF(OR(Incidencias!M53="Abierta",Incidencias!M53="En proceso",Incidencias!M53="Info cliente")=TRUE,"En curso",IF(Incidencias!M53="Descartada","Descartada","Entregada"))) -> Entregada | D29: =IF(C29="En curso", IF(Incidencias!#REF!="Sí","Bloqueante", IF(Incidencias!#REF!="No","No bloqueante","NA")),"NA") -> NA | E29: =IF(C29="En curso", IF(Incidencias!#REF!="Usuario","Usuario", IF(Incidencias!#REF!="Proceso","Proceso","NA")),"NA") -> NA
A30: =Incidencias!B48 -> 0 | B30: =IF(Incidencias!E54="Mejora","Mejora","Incidencia") -> Incidencia | C30: =IF(Incidencias!E54="Mejora","NA",IF(OR(Incidencias!M54="Abierta",Incidencias!M54="En proceso",Incidencias!M54="Info cliente")=TRUE,"En curso",IF(Incidencias!M54="Descartada","Descartada","Entregada"))) -> Entregada | D30: =IF(C30="En curso", IF(Incidencias!#REF!="Sí","Bloqueante", IF(Incidencias!#REF!="No","No bloqueante","NA")),"NA") -> NA | E30: =IF(C30="En curso", IF(Incidencias!#REF!="Usuario","Usuario", IF(Incidencias!#REF!="Proceso","Proceso","NA")),"NA") -> NA
A31: =Incidencias!B49 -> 0 | B31: =IF(Incidencias!E55="Mejora","Mejora","Incidencia") -> Incidencia | C31: =IF(Incidencias!E55="Mejora","NA",IF(OR(Incidencias!M55="Abierta",Incidencias!M55="En proceso",Incidencias!M55="Info cliente")=TRUE,"En curso",IF(Incidencias!M55="Descartada","Descartada","Entregada"))) -> Entregada | D31: =IF(C31="En curso", IF(Incidencias!#REF!="Sí","Bloqueante", IF(Incidencias!#REF!="No","No bloqueante","NA")),"NA") -> NA | E31: =IF(C31="En curso", IF(Incidencias!#REF!="Usuario","Usuario", IF(Incidencias!#REF!="Proceso","Proceso","NA")),"NA") -> NA
A32: =Incidencias!B50 -> 0 | B32: =IF(Incidencias!E56="Mejora","Mejora","Incidencia") -> Incidencia | C32: =IF(Incidencias!E56="Mejora","NA",IF(OR(Incidencias!M56="Abierta",Incidencias!M56="En proceso",Incidencias!M56="Info cliente")=TRUE,"En curso",IF(Incidencias!M56="Descartada","Descartada","Entregada"))) -> Entregada | D32: =IF(C32="En curso", IF(Incidencias!#REF!="Sí","Bloqueante", IF(Incidencias!#REF!="No","No bloqueante","NA")),"NA") -> NA | E32: =IF(C32="En curso", IF(Incidencias!#REF!="Usuario","Usuario", IF(Incidencias!#REF!="Proceso","Proceso","NA")),"NA") -> NA
A33: =Incidencias!B51 -> 0 | B33: =IF(Incidencias!E57="Mejora","Mejora","Incidencia") -> Incidencia | C33: =IF(Incidencias!E57="Mejora","NA",IF(OR(Incidencias!M57="Abierta",Incidencias!M57="En proceso",Incidencias!M57="Info cliente")=TRUE,"En curso",IF(Incidencias!M57="Descartada","Descartada","Entregada"))) -> Entregada | D33: =IF(C33="En curso", IF(Incidencias!#REF!="Sí","Bloqueante", IF(Incidencias!#REF!="No","No bloqueante","NA")),"NA") -> NA | E33: =IF(C33="En curso", IF(Incidencias!#REF!="Usuario","Usuario", IF(Incidencias!#REF!="Proceso","Proceso","NA")),"NA") -> NA
A34: =Incidencias!B52 -> 0 | B34: =IF(Incidencias!E58="Mejora","Mejora","Incidencia") -> Incidencia | C34: =IF(Incidencias!E58="Mejora","NA",IF(OR(Incidencias!M58="Abierta",Incidencias!M58="En proceso",Incidencias!M58="Info cliente")=TRUE,"En curso",IF(Incidencias!M58="Descartada","Descartada","Entregada"))) -> Entregada | D34: =IF(C34="En curso", IF(Incidencias!#REF!="Sí","Bloqueante", IF(Incidencias!#REF!="No","No bloqueante","NA")),"NA") -> NA | E34: =IF(C34="En curso", IF(Incidencias!#REF!="Usuario","Usuario", IF(Incidencias!#REF!="Proceso","Proceso","NA")),"NA") -> NA
A35: =Incidencias!B53 -> 0 | B35: =IF(Incidencias!E59="Mejora","Mejora","Incidencia") -> Incidencia | C35: =IF(Incidencias!E59="Mejora","NA",IF(OR(Incidencias!M59="Abierta",Incidencias!M59="En proceso",Incidencias!M59="Info cliente")=TRUE,"En curso",IF(Incidencias!M59="Descartada","Descartada","Entregada"))) -> Entregada | D35: =IF(C35="En curso", IF(Incidencias!#REF!="Sí","Bloqueante", IF(Incidencias!#REF!="No","No bloqueante","NA")),"NA") -> NA | E35: =IF(C35="En curso", IF(Incidencias!#REF!="Usuario","Usuario", IF(Incidencias!#REF!="Proceso","Proceso","NA")),"NA") -> NA
A36: =Incidencias!B54 -> 0 | B36: =IF(Incidencias!E60="Mejora","Mejora","Incidencia") -> Incidencia | C36: =IF(Incidencias!E60="Mejora","NA",IF(OR(Incidencias!M60="Abierta",Incidencias!M60="En proceso",Incidencias!M60="Info cliente")=TRUE,"En curso",IF(Incidencias!M60="Descartada","Descartada","Entregada"))) -> Entregada | D36: =IF(C36="En curso", IF(Incidencias!#REF!="Sí","Bloqueante", IF(Incidencias!#REF!="No","No bloqueante","NA")),"NA") -> NA | E36: =IF(C36="En curso", IF(Incidencias!#REF!="Usuario","Usuario", IF(Incidencias!#REF!="Proceso","Proceso","NA")),"NA") -> NA
A37: =Incidencias!B55 -> 0 | B37: =IF(Incidencias!E62="Mejora","Mejora","Incidencia") -> Incidencia | C37: =IF(Incidencias!E62="Mejora","NA",IF(OR(Incidencias!M62="Abierta",Incidencias!M62="En proceso",Incidencias!M62="Info cliente")=TRUE,"En curso",IF(Incidencias!M62="Descartada","Descartada","Entregada"))) -> Entregada | D37: =IF(C37="En curso", IF(Incidencias!#REF!="Sí","Bloqueante", IF(Incidencias!#REF!="No","No bloqueante","NA")),"NA") -> NA | E37: =IF(C37="En curso", IF(Incidencias!#REF!="Usuario","Usuario", IF(Incidencias!#REF!="Proceso","Proceso","NA")),"NA") -> NA
A38: =Incidencias!B56 -> 0 | B38: =IF(Incidencias!E63="Mejora","Mejora","Incidencia") -> Incidencia | C38: =IF(Incidencias!E63="Mejora","NA",IF(OR(Incidencias!M63="Abierta",Incidencias!M63="En proceso",Incidencias!M63="Info cliente")=TRUE,"En curso",IF(Incidencias!M63="Descartada","Descartada","Entregada"))) -> Entregada | D38: =IF(C38="En curso", IF(Incidencias!#REF!="Sí","Bloqueante", IF(Incidencias!#REF!="No","No bloqueante","NA")),"NA") -> NA | E38: =IF(C38="En curso", IF(Incidencias!#REF!="Usuario","Usuario", IF(Incidencias!#REF!="Proceso","Proceso","NA")),"NA") -> NA
A39: =Incidencias!B57 -> 0 | B39: =IF(Incidencias!E65="Mejora","Mejora","Incidencia") -> Incidencia | C39: =IF(Incidencias!E65="Mejora","NA",IF(OR(Incidencias!M65="Abierta",Incidencias!M65="En proceso",Incidencias!M65="Info cliente")=TRUE,"En curso",IF(Incidencias!M65="Descartada","Descartada","Entregada"))) -> Entregada | D39: =IF(C39="En curso", IF(Incidencias!#REF!="Sí","Bloqueante", IF(Incidencias!#REF!="No","No bloqueante","NA")),"NA") -> NA | E39: =IF(C39="En curso", IF(Incidencias!#REF!="Usuario","Usuario", IF(Incidencias!#REF!="Proceso","Proceso","NA")),"NA") -> NA
A40: =Incidencias!B58 -> 0 | B40: =IF(Incidencias!E66="Mejora","Mejora","Incidencia") -> Incidencia | C40: =IF(Incidencias!E66="Mejora","NA",IF(OR(Incidencias!M66="Abierta",Incidencias!M66="En proceso",Incidencias!M66="Info cliente")=TRUE,"En curso",IF(Incidencias!M66="Descartada","Descartada","Entregada"))) -> Entregada | D40: =IF(C40="En curso", IF(Incidencias!#REF!="Sí","Bloqueante", IF(Incidencias!#REF!="No","No bloqueante","NA")),"NA") -> NA | E40: =IF(C40="En curso", IF(Incidencias!#REF!="Usuario","Usuario", IF(Incidencias!#REF!="Proceso","Proceso","NA")),"NA") -> NA
...

Sheet Datos
A1: Información para los combos rellenables del listado de incidencias. Actualizar responsables de cliente y propios al proyecto en concreto, y revisar el resto de puntos por si hubiese cambios.
A2: Estado | D2: Prioridad | F2: Tipo | H2: Módulo | J2: Bloque | L2: Resonsable EUR | N2: Sistema | P2: Responsable equipo Altim | R2: Key User | T2: Riesgo | V2: Bloque | X2: Tipologia | AB2: Pais | AD2: Motivo de Retraso
A3: 1En proceso | B3: Altim | D3: Alta | F3: Consulta | H3: Finanzas | J3: Finanzas | L3: Alberto | N3: S4/hana | P3: ADM | R3: Alberto | T3: Alto | V3: UATs #1 - Hasta 20/01/2026 | X3: Procesos de EUROVAL | AB3: ES | AD3: Nuevos Requerimientos
A4: 2Retrasada Altim | B4: Altim | D4: Baja | F4: Consulta | H4: CONTROL | J4: Compras | L4: Manuel | N4: SGA | P4: Amal H. | R4: Manuel | T4: Medio | V4: UATs #2 - Desde 21/01/2026 hasta Go-Live | X4: Análisis y Diseño funcional | AB4: PT | AD4: Error en planificación
A5: 3Entregada | B5: EUR | D5: Sin prioridad | F5: Evolutivo | H5: Integración | J5: Ventas | L5: Yolanda | N5: Navision | P5: Eneko C. | R5: Yolanda | T5: Bajo | X5: Configuración y desarrollos. | AD5: Sin retraso
A6: 4Pte Info EUR | B6: EUR | D6: Crítica | F6: Formación | H6: IT | J6: Control de gestión | L6: Paula | N6: Interface | P6: Miguel E. | R6: Paula | T6: N/A | X6: Calidad de Datos | AD6: Falta Recurso del Área
A7: 5Pte de Pruebas EUR | B7: EUR | D7: Media | F7: Gestión | H7: COMP | L7: Marisa | N7: SGA | P7: Jose Miguel J. | R7: Marisa | X7: Integraciones | AD7: Problemas con el usuario
A8: 6Retrasada EUR | B8: EUR | F8: Incidencia | H8: VENTAS | L8: Fernando | P8: Ricardo M. | R8: Fernando | X8: Formación. | AD8: Revision por parte de MP
A9: 7Parada por EUR | B9: EUR | F9: Petición | P9: Gloria B. | AD9: Cambio de prioridad MP
A10: 8Abierta | B10: EUR | F10: Preventiva | P10: Paco G. | AD10: Retraso en el Trabajo Altim
A11: 9Nueva | B11: EUR | F11: Proyecto | P11: Daniel CH.
A12: 91Cerrada | B12: Altim
A13: 92Descartada | B13: EUR
A14: 93Duplicada | B14: Altim

Sheet Status
A2: Bloque | B2: (Todas)
A4: Cuenta de Nº | B4: Etiquetas de columna
A5: Etiquetas de fila | B5: Finanzas | C5: Gestión | D5: Integración | E5: IT | F5: O2C | G5: P2P | H5: Total general
A6: 1En proceso | B6: 2 | C6: 1 | D6: 1 | F6: 6 | G6: 3 | H6: 13
A7: 3Entregada | B7: 1 | F7: 5 | G7: 3 | H7: 9
A8: 4Pte Info MP | B8: 13 | D8: 1 | F8: 2 | G8: 2 | H8: 18
A9: 5Pte de Pruebas MP | D9: 1 | F9: 2 | H9: 3
A10: 7Parada por MP | B10: 7 | C10: 2 | D10: 1 | F10: 4 | G10: 3 | H10: 17
A11: 8Abierta | B11: 1 | D11: 3 | F11: 24 | G11: 17 | H11: 45
A12: 91Cerrada | B12: 46 | C12: 3 | D12: 1 | E12: 1 | F12: 7 | G12: 19 | H12: 77
A13: 92Descartada | B13: 5 | G13: 3 | H13: 8
A14: 93Duplicada | B14: 2 | F14: 3 | H14: 5
A15: 9Nueva | B15: 1 | D15: 1 | F15: 3 | G15: 4 | H15: 9
A16: Total general | B16: 78 | C16: 6 | D16: 9 | E16: 1 | F16: 56 | G16: 54 | H16: 204
